/home/admin1/frappe-bench/env/lib/python3.10/site-packages/botocore/httpsession.py:19: DeprecationWarning: 'urllib3.contrib.pyopenssl' module is deprecated and will be removed in a future release of urllib3 2.x. Read more in this issue: https://github.com/urllib3/urllib3/issues/2680
  from urllib3.contrib.pyopenssl import orig_util_SSLContext as SSLContext
/home/admin1/frappe-bench/env/lib/python3.10/site-packages/botocore/httpsession.py:19: DeprecationWarning: 'urllib3.contrib.pyopenssl' module is deprecated and will be removed in a future release of urllib3 2.x. Read more in this issue: https://github.com/urllib3/urllib3/issues/2680
  from urllib3.contrib.pyopenssl import orig_util_SSLContext as SSLContext
/home/admin1/frappe-bench/env/lib/python3.10/site-packages/botocore/httpsession.py:19: DeprecationWarning: 'urllib3.contrib.pyopenssl' module is deprecated and will be removed in a future release of urllib3 2.x. Read more in this issue: https://github.com/urllib3/urllib3/issues/2680
  from urllib3.contrib.pyopenssl import orig_util_SSLContext as SSLContext
Exception in thread Thread-1:
Traceback (most recent call last):
  File "/usr/lib/python3.10/threading.py", line 1016, in _bootstrap_inner
    self.run()
  File "/home/admin1/frappe-bench/env/lib/python3.10/site-packages/redis/client.py", line 3718, in run
    pubsub.get_message(ignore_subscribe_messages=True,
  File "/home/admin1/frappe-bench/env/lib/python3.10/site-packages/redis/client.py", line 3617, in get_message
    response = self.parse_response(block=False, timeout=timeout)
  File "/home/admin1/frappe-bench/env/lib/python3.10/site-packages/redis/client.py", line 3503, in parse_response
    if not block and not conn.can_read(timeout=timeout):
  File "/home/admin1/frappe-bench/env/lib/python3.10/site-packages/redis/connection.py", line 734, in can_read
    return self._parser.can_read(timeout)
  File "/home/admin1/frappe-bench/env/lib/python3.10/site-packages/redis/connection.py", line 416, in can_read
    return self.read_from_socket(timeout=timeout,
  File "/home/admin1/frappe-bench/env/lib/python3.10/site-packages/redis/connection.py", line 429, in read_from_socket
    raise ConnectionError(SERVER_CLOSED_CONNECTION_ERROR)
redis.exceptions.ConnectionError: Connection closed by server.
Exception in thread Thread-1:
Traceback (most recent call last):
  File "/usr/lib/python3.10/threading.py", line 1016, in _bootstrap_inner
    self.run()
  File "/home/admin1/frappe-bench/env/lib/python3.10/site-packages/redis/client.py", line 3718, in run
    pubsub.get_message(ignore_subscribe_messages=True,
  File "/home/admin1/frappe-bench/env/lib/python3.10/site-packages/redis/client.py", line 3617, in get_message
    response = self.parse_response(block=False, timeout=timeout)
  File "/home/admin1/frappe-bench/env/lib/python3.10/site-packages/redis/client.py", line 3503, in parse_response
    if not block and not conn.can_read(timeout=timeout):
  File "/home/admin1/frappe-bench/env/lib/python3.10/site-packages/redis/connection.py", line 734, in can_read
    return self._parser.can_read(timeout)
  File "/home/admin1/frappe-bench/env/lib/python3.10/site-packages/redis/connection.py", line 416, in can_read
    return self.read_from_socket(timeout=timeout,
  File "/home/admin1/frappe-bench/env/lib/python3.10/site-packages/redis/connection.py", line 429, in read_from_socket
    raise ConnectionError(SERVER_CLOSED_CONNECTION_ERROR)
redis.exceptions.ConnectionError: Connection closed by server.
Exception in thread Thread-1:
Traceback (most recent call last):
  File "/usr/lib/python3.10/threading.py", line 1016, in _bootstrap_inner
    self.run()
  File "/home/admin1/frappe-bench/env/lib/python3.10/site-packages/redis/client.py", line 3718, in run
    pubsub.get_message(ignore_subscribe_messages=True,
  File "/home/admin1/frappe-bench/env/lib/python3.10/site-packages/redis/client.py", line 3617, in get_message
    response = self.parse_response(block=False, timeout=timeout)
  File "/home/admin1/frappe-bench/env/lib/python3.10/site-packages/redis/client.py", line 3503, in parse_response
    if not block and not conn.can_read(timeout=timeout):
  File "/home/admin1/frappe-bench/env/lib/python3.10/site-packages/redis/connection.py", line 734, in can_read
    return self._parser.can_read(timeout)
  File "/home/admin1/frappe-bench/env/lib/python3.10/site-packages/redis/connection.py", line 416, in can_read
    return self.read_from_socket(timeout=timeout,
  File "/home/admin1/frappe-bench/env/lib/python3.10/site-packages/redis/connection.py", line 429, in read_from_socket
    raise ConnectionError(SERVER_CLOSED_CONNECTION_ERROR)
redis.exceptions.ConnectionError: Connection closed by server.
/home/admin1/frappe-bench/env/lib/python3.10/site-packages/botocore/httpsession.py:19: DeprecationWarning: 'urllib3.contrib.pyopenssl' module is deprecated and will be removed in a future release of urllib3 2.x. Read more in this issue: https://github.com/urllib3/urllib3/issues/2680
  from urllib3.contrib.pyopenssl import orig_util_SSLContext as SSLContext
fatal: No remote configured to list refs from.
Exception in thread Thread-1:
Traceback (most recent call last):
  File "/usr/lib/python3.10/threading.py", line 1016, in _bootstrap_inner
    self.run()
  File "/home/admin1/frappe-bench/env/lib/python3.10/site-packages/redis/client.py", line 3718, in run
    pubsub.get_message(ignore_subscribe_messages=True,
  File "/home/admin1/frappe-bench/env/lib/python3.10/site-packages/redis/client.py", line 3617, in get_message
    response = self.parse_response(block=False, timeout=timeout)
  File "/home/admin1/frappe-bench/env/lib/python3.10/site-packages/redis/client.py", line 3503, in parse_response
    if not block and not conn.can_read(timeout=timeout):
  File "/home/admin1/frappe-bench/env/lib/python3.10/site-packages/redis/connection.py", line 734, in can_read
    return self._parser.can_read(timeout)
  File "/home/admin1/frappe-bench/env/lib/python3.10/site-packages/redis/connection.py", line 416, in can_read
    return self.read_from_socket(timeout=timeout,
  File "/home/admin1/frappe-bench/env/lib/python3.10/site-packages/redis/connection.py", line 429, in read_from_socket
    raise ConnectionError(SERVER_CLOSED_CONNECTION_ERROR)
redis.exceptions.ConnectionError: Connection closed by server.
Exception in thread Thread-1:
Traceback (most recent call last):
  File "/usr/lib/python3.10/threading.py", line 1016, in _bootstrap_inner
    self.run()
  File "/home/admin1/frappe-bench/env/lib/python3.10/site-packages/redis/client.py", line 3718, in run
    pubsub.get_message(ignore_subscribe_messages=True,
  File "/home/admin1/frappe-bench/env/lib/python3.10/site-packages/redis/client.py", line 3617, in get_message
    response = self.parse_response(block=False, timeout=timeout)
  File "/home/admin1/frappe-bench/env/lib/python3.10/site-packages/redis/client.py", line 3503, in parse_response
    if not block and not conn.can_read(timeout=timeout):
  File "/home/admin1/frappe-bench/env/lib/python3.10/site-packages/redis/connection.py", line 734, in can_read
    return self._parser.can_read(timeout)
  File "/home/admin1/frappe-bench/env/lib/python3.10/site-packages/redis/connection.py", line 416, in can_read
    return self.read_from_socket(timeout=timeout,
  File "/home/admin1/frappe-bench/env/lib/python3.10/site-packages/redis/connection.py", line 429, in read_from_socket
    raise ConnectionError(SERVER_CLOSED_CONNECTION_ERROR)
redis.exceptions.ConnectionError: Connection closed by server.
Exception in thread Thread-1:
Traceback (most recent call last):
  File "/usr/lib/python3.10/threading.py", line 1016, in _bootstrap_inner
    self.run()
  File "/home/admin1/frappe-bench/env/lib/python3.10/site-packages/redis/client.py", line 3718, in run
    pubsub.get_message(ignore_subscribe_messages=True,
  File "/home/admin1/frappe-bench/env/lib/python3.10/site-packages/redis/client.py", line 3617, in get_message
    response = self.parse_response(block=False, timeout=timeout)
  File "/home/admin1/frappe-bench/env/lib/python3.10/site-packages/redis/client.py", line 3503, in parse_response
    if not block and not conn.can_read(timeout=timeout):
  File "/home/admin1/frappe-bench/env/lib/python3.10/site-packages/redis/connection.py", line 734, in can_read
    return self._parser.can_read(timeout)
  File "/home/admin1/frappe-bench/env/lib/python3.10/site-packages/redis/connection.py", line 416, in can_read
    return self.read_from_socket(timeout=timeout,
  File "/home/admin1/frappe-bench/env/lib/python3.10/site-packages/redis/connection.py", line 429, in read_from_socket
    raise ConnectionError(SERVER_CLOSED_CONNECTION_ERROR)
redis.exceptions.ConnectionError: Connection closed by server.
Exception in thread Thread-1:
Traceback (most recent call last):
  File "/usr/lib/python3.10/threading.py", line 1016, in _bootstrap_inner
    self.run()
  File "/home/admin1/frappe-bench/env/lib/python3.10/site-packages/redis/client.py", line 3718, in run
    pubsub.get_message(ignore_subscribe_messages=True,
  File "/home/admin1/frappe-bench/env/lib/python3.10/site-packages/redis/client.py", line 3617, in get_message
    response = self.parse_response(block=False, timeout=timeout)
  File "/home/admin1/frappe-bench/env/lib/python3.10/site-packages/redis/client.py", line 3503, in parse_response
    if not block and not conn.can_read(timeout=timeout):
  File "/home/admin1/frappe-bench/env/lib/python3.10/site-packages/redis/connection.py", line 734, in can_read
    return self._parser.can_read(timeout)
  File "/home/admin1/frappe-bench/env/lib/python3.10/site-packages/redis/connection.py", line 416, in can_read
    return self.read_from_socket(timeout=timeout,
  File "/home/admin1/frappe-bench/env/lib/python3.10/site-packages/redis/connection.py", line 429, in read_from_socket
    raise ConnectionError(SERVER_CLOSED_CONNECTION_ERROR)
redis.exceptions.ConnectionError: Connection closed by server.
/home/admin1/frappe-bench/env/lib/python3.10/site-packages/botocore/httpsession.py:19: DeprecationWarning: 'urllib3.contrib.pyopenssl' module is deprecated and will be removed in a future release of urllib3 2.x. Read more in this issue: https://github.com/urllib3/urllib3/issues/2680
  from urllib3.contrib.pyopenssl import orig_util_SSLContext as SSLContext
/home/admin1/frappe-bench/env/lib/python3.10/site-packages/botocore/httpsession.py:19: DeprecationWarning: 'urllib3.contrib.pyopenssl' module is deprecated and will be removed in a future release of urllib3 2.x. Read more in this issue: https://github.com/urllib3/urllib3/issues/2680
  from urllib3.contrib.pyopenssl import orig_util_SSLContext as SSLContext
/home/admin1/frappe-bench/env/lib/python3.10/site-packages/botocore/httpsession.py:19: DeprecationWarning: 'urllib3.contrib.pyopenssl' module is deprecated and will be removed in a future release of urllib3 2.x. Read more in this issue: https://github.com/urllib3/urllib3/issues/2680
  from urllib3.contrib.pyopenssl import orig_util_SSLContext as SSLContext
fatal: No remote configured to list refs from.
/home/admin1/frappe-bench/env/lib/python3.10/site-packages/botocore/httpsession.py:19: DeprecationWarning: 'urllib3.contrib.pyopenssl' module is deprecated and will be removed in a future release of urllib3 2.x. Read more in this issue: https://github.com/urllib3/urllib3/issues/2680
  from urllib3.contrib.pyopenssl import orig_util_SSLContext as SSLContext
fatal: No remote configured to list refs from.
/home/admin1/frappe-bench/env/lib/python3.10/site-packages/botocore/httpsession.py:19: DeprecationWarning: 'urllib3.contrib.pyopenssl' module is deprecated and will be removed in a future release of urllib3 2.x. Read more in this issue: https://github.com/urllib3/urllib3/issues/2680
  from urllib3.contrib.pyopenssl import orig_util_SSLContext as SSLContext
fatal: No remote configured to list refs from.
/home/admin1/frappe-bench/env/lib/python3.10/site-packages/botocore/httpsession.py:19: DeprecationWarning: 'urllib3.contrib.pyopenssl' module is deprecated and will be removed in a future release of urllib3 2.x. Read more in this issue: https://github.com/urllib3/urllib3/issues/2680
  from urllib3.contrib.pyopenssl import orig_util_SSLContext as SSLContext
Traceback (most recent call last):
  File "/home/admin1/frappe-bench/env/lib/python3.10/site-packages/redis/connection.py", line 559, in connect
    sock = self._connect()
  File "/home/admin1/frappe-bench/env/lib/python3.10/site-packages/redis/connection.py", line 615, in _connect
    raise err
  File "/home/admin1/frappe-bench/env/lib/python3.10/site-packages/redis/connection.py", line 603, in _connect
    sock.connect(socket_address)
ConnectionRefusedError: [Errno 111] Connection refused

During handling of the above exception, another exception occurred:

Traceback (most recent call last):
  File "/usr/lib/python3.10/runpy.py", line 196, in _run_module_as_main
    return _run_code(code, main_globals, None,
  File "/usr/lib/python3.10/runpy.py", line 86, in _run_code
    exec(code, run_globals)
  File "/home/admin1/frappe-bench/apps/frappe/frappe/utils/bench_helper.py", line 109, in <module>
    main()
  File "/home/admin1/frappe-bench/apps/frappe/frappe/utils/bench_helper.py", line 18, in main
    click.Group(commands=commands)(prog_name="bench")
  File "/home/admin1/frappe-bench/env/lib/python3.10/site-packages/click/core.py", line 1157, in __call__
    return self.main(*args, **kwargs)
  File "/home/admin1/frappe-bench/env/lib/python3.10/site-packages/click/core.py", line 1078, in main
    rv = self.invoke(ctx)
  File "/home/admin1/frappe-bench/env/lib/python3.10/site-packages/click/core.py", line 1688, in invoke
    return _process_result(sub_ctx.command.invoke(sub_ctx))
  File "/home/admin1/frappe-bench/env/lib/python3.10/site-packages/click/core.py", line 1688, in invoke
    return _process_result(sub_ctx.command.invoke(sub_ctx))
  File "/home/admin1/frappe-bench/env/lib/python3.10/site-packages/click/core.py", line 1434, in invoke
    return ctx.invoke(self.callback, **ctx.params)
  File "/home/admin1/frappe-bench/env/lib/python3.10/site-packages/click/core.py", line 783, in invoke
    return __callback(*args, **kwargs)
  File "/home/admin1/frappe-bench/apps/frappe/frappe/commands/scheduler.py", line 206, in start_worker
    start_worker(
  File "/home/admin1/frappe-bench/apps/frappe/frappe/utils/background_jobs.py", line 264, in start_worker
    worker.work(
  File "/home/admin1/frappe-bench/env/lib/python3.10/site-packages/rq/worker.py", line 645, in work
    self.unsubscribe()
  File "/home/admin1/frappe-bench/env/lib/python3.10/site-packages/rq/worker.py", line 550, in unsubscribe
    self.pubsub.unsubscribe()
  File "/home/admin1/frappe-bench/env/lib/python3.10/site-packages/redis/client.py", line 3600, in unsubscribe
    return self.execute_command('UNSUBSCRIBE', *args)
  File "/home/admin1/frappe-bench/env/lib/python3.10/site-packages/redis/client.py", line 3466, in execute_command
    self.connection = self.connection_pool.get_connection(
  File "/home/admin1/frappe-bench/env/lib/python3.10/site-packages/redis/connection.py", line 1192, in get_connection
    connection.connect()
  File "/home/admin1/frappe-bench/env/lib/python3.10/site-packages/redis/connection.py", line 563, in connect
    raise ConnectionError(self._error_message(e))
redis.exceptions.ConnectionError: Error 111 connecting to localhost:11000. Connection refused.
/home/admin1/frappe-bench/env/lib/python3.10/site-packages/botocore/httpsession.py:19: DeprecationWarning: 'urllib3.contrib.pyopenssl' module is deprecated and will be removed in a future release of urllib3 2.x. Read more in this issue: https://github.com/urllib3/urllib3/issues/2680
  from urllib3.contrib.pyopenssl import orig_util_SSLContext as SSLContext
/home/admin1/frappe-bench/env/lib/python3.10/site-packages/botocore/httpsession.py:19: DeprecationWarning: 'urllib3.contrib.pyopenssl' module is deprecated and will be removed in a future release of urllib3 2.x. Read more in this issue: https://github.com/urllib3/urllib3/issues/2680
  from urllib3.contrib.pyopenssl import orig_util_SSLContext as SSLContext
/home/admin1/frappe-bench/env/lib/python3.10/site-packages/botocore/httpsession.py:19: DeprecationWarning: 'urllib3.contrib.pyopenssl' module is deprecated and will be removed in a future release of urllib3 2.x. Read more in this issue: https://github.com/urllib3/urllib3/issues/2680
  from urllib3.contrib.pyopenssl import orig_util_SSLContext as SSLContext
fatal: No remote configured to list refs from.
Traceback (most recent call last):
  File "/home/admin1/frappe-bench/env/lib/python3.10/site-packages/redis/connection.py", line 559, in connect
    sock = self._connect()
  File "/home/admin1/frappe-bench/env/lib/python3.10/site-packages/redis/connection.py", line 615, in _connect
    raise err
  File "/home/admin1/frappe-bench/env/lib/python3.10/site-packages/redis/connection.py", line 603, in _connect
    sock.connect(socket_address)
ConnectionRefusedError: [Errno 111] Connection refused

During handling of the above exception, another exception occurred:

Traceback (most recent call last):
  File "/usr/lib/python3.10/runpy.py", line 196, in _run_module_as_main
    return _run_code(code, main_globals, None,
  File "/usr/lib/python3.10/runpy.py", line 86, in _run_code
    exec(code, run_globals)
  File "/home/admin1/frappe-bench/apps/frappe/frappe/utils/bench_helper.py", line 109, in <module>
    main()
  File "/home/admin1/frappe-bench/apps/frappe/frappe/utils/bench_helper.py", line 18, in main
    click.Group(commands=commands)(prog_name="bench")
  File "/home/admin1/frappe-bench/env/lib/python3.10/site-packages/click/core.py", line 1157, in __call__
    return self.main(*args, **kwargs)
  File "/home/admin1/frappe-bench/env/lib/python3.10/site-packages/click/core.py", line 1078, in main
    rv = self.invoke(ctx)
  File "/home/admin1/frappe-bench/env/lib/python3.10/site-packages/click/core.py", line 1688, in invoke
    return _process_result(sub_ctx.command.invoke(sub_ctx))
  File "/home/admin1/frappe-bench/env/lib/python3.10/site-packages/click/core.py", line 1688, in invoke
    return _process_result(sub_ctx.command.invoke(sub_ctx))
  File "/home/admin1/frappe-bench/env/lib/python3.10/site-packages/click/core.py", line 1434, in invoke
    return ctx.invoke(self.callback, **ctx.params)
  File "/home/admin1/frappe-bench/env/lib/python3.10/site-packages/click/core.py", line 783, in invoke
    return __callback(*args, **kwargs)
  File "/home/admin1/frappe-bench/apps/frappe/frappe/commands/scheduler.py", line 206, in start_worker
    start_worker(
  File "/home/admin1/frappe-bench/apps/frappe/frappe/utils/background_jobs.py", line 264, in start_worker
    worker.work(
  File "/home/admin1/frappe-bench/env/lib/python3.10/site-packages/rq/worker.py", line 645, in work
    self.unsubscribe()
  File "/home/admin1/frappe-bench/env/lib/python3.10/site-packages/rq/worker.py", line 550, in unsubscribe
    self.pubsub.unsubscribe()
  File "/home/admin1/frappe-bench/env/lib/python3.10/site-packages/redis/client.py", line 3600, in unsubscribe
    return self.execute_command('UNSUBSCRIBE', *args)
  File "/home/admin1/frappe-bench/env/lib/python3.10/site-packages/redis/client.py", line 3466, in execute_command
    self.connection = self.connection_pool.get_connection(
  File "/home/admin1/frappe-bench/env/lib/python3.10/site-packages/redis/connection.py", line 1192, in get_connection
    connection.connect()
  File "/home/admin1/frappe-bench/env/lib/python3.10/site-packages/redis/connection.py", line 563, in connect
    raise ConnectionError(self._error_message(e))
redis.exceptions.ConnectionError: Error 111 connecting to localhost:11000. Connection refused.
